{
  "timestamp": "2025-07-13T10:47:46.420962",
  "total_duration": 1.578103,
  "total_tests": 4,
  "passed": 0,
  "failed": 4,
  "errors": 0,
  "timeouts": 0,
  "skipped": 0,
  "success_rate": 0.0,
  "results": [
    {
      "name": "validation_tests",
      "test_type": "unit",
      "status": "failed",
      "duration": 0.868262,
      "start_time": "2025-07-13T10:47:44.847266",
      "end_time": "2025-07-13T10:47:45.715528",
      "output": "\u001b[1m============================= test session starts ==============================\u001b[0m\nplatform linux -- Python 3.12.11, pytest-8.4.1, pluggy-1.6.0 -- /data/data/com.termux/files/usr/bin/python3\ncachedir: .pytest_cache\nrootdir: /data/data/com.termux/files/home/projexta/voiceflow\nconfigfile: pytest.ini\nplugins: asyncio-1.0.0, anyio-4.9.0\nasyncio: mode=Mode.STRICT, asyncio_default_fixture_loop_scope=None, asyncio_default_test_loop_scope=function\n\u001b[1mcollecting ... \u001b[0mcollected 0 items\n\n\u001b[33m============================ \u001b[33mno tests ran\u001b[0m\u001b[33m in 0.09s\u001b[0m\u001b[33m =============================\u001b[0m\n",
      "error_output": "",
      "exit_code": 5,
      "metadata": {}
    },
    {
      "name": "config_tests",
      "test_type": "unit",
      "status": "failed",
      "duration": 1.064783,
      "start_time": "2025-07-13T10:47:44.846019",
      "end_time": "2025-07-13T10:47:45.910802",
      "output": "\u001b[1m============================= test session starts ==============================\u001b[0m\nplatform linux -- Python 3.12.11, pytest-8.4.1, pluggy-1.6.0 -- /data/data/com.termux/files/usr/bin/python3\ncachedir: .pytest_cache\nrootdir: /data/data/com.termux/files/home/projexta/voiceflow\nconfigfile: pytest.ini\nplugins: asyncio-1.0.0, anyio-4.9.0\nasyncio: mode=Mode.STRICT, asyncio_default_fixture_loop_scope=None, asyncio_default_test_loop_scope=function\n\u001b[1mcollecting ... \u001b[0mcollected 21 items\n\ntests/test_config.py::TestVoiceFlowConfig::test_initialization_creates_directory \u001b[32mPASSED\u001b[0m\u001b[32m [  4%]\u001b[0m\ntests/test_config.py::TestVoiceFlowConfig::test_default_configuration \u001b[32mPASSED\u001b[0m\u001b[32m [  9%]\u001b[0m\ntests/test_config.py::TestVoiceFlowConfig::test_load_config_file \u001b[32mPASSED\u001b[0m\u001b[32m  [ 14%]\u001b[0m\ntests/test_config.py::TestVoiceFlowConfig::test_load_config_file_error \u001b[32mPASSED\u001b[0m\u001b[32m [ 19%]\u001b[0m\ntests/test_config.py::TestVoiceFlowConfig::test_custom_config_path \u001b[32mPASSED\u001b[0m\u001b[32m [ 23%]\u001b[0m\ntests/test_config.py::TestVoiceFlowConfig::test_environment_variables \u001b[32mPASSED\u001b[0m\u001b[32m [ 28%]\u001b[0m\ntests/test_config.py::TestVoiceFlowConfig::test_environment_variables_invalid_values \u001b[32mPASSED\u001b[0m\u001b[32m [ 33%]\u001b[0m\ntests/test_config.py::TestVoiceFlowConfig::test_priority_order \u001b[32mPASSED\u001b[0m\u001b[32m    [ 38%]\u001b[0m\ntests/test_config.py::TestVoiceFlowConfig::test_get_method \u001b[32mPASSED\u001b[0m\u001b[32m        [ 42%]\u001b[0m\ntests/test_config.py::TestVoiceFlowConfig::test_set_method \u001b[32mPASSED\u001b[0m\u001b[32m        [ 47%]\u001b[0m\ntests/test_config.py::TestVoiceFlowConfig::test_get_section \u001b[32mPASSED\u001b[0m\u001b[32m       [ 52%]\u001b[0m\ntests/test_config.py::TestVoiceFlowConfig::test_save_configuration \u001b[32mPASSED\u001b[0m\u001b[32m [ 57%]\u001b[0m\ntests/test_config.py::TestVoiceFlowConfig::test_save_configuration_error \u001b[32mPASSED\u001b[0m\u001b[32m [ 61%]\u001b[0m\ntests/test_config.py::TestVoiceFlowConfig::test_to_dict \u001b[31mFAILED\u001b[0m\u001b[31m           [ 66%]\u001b[0m\ntests/test_config.py::TestVoiceFlowConfig::test_create_example_config \u001b[32mPASSED\u001b[0m\u001b[31m [ 71%]\u001b[0m\ntests/test_config.py::TestVoiceFlowConfig::test_merge_config \u001b[32mPASSED\u001b[0m\u001b[31m      [ 76%]\u001b[0m\ntests/test_config.py::TestGlobalConfigFunctions::test_get_config_singleton \u001b[32mPASSED\u001b[0m\u001b[31m [ 80%]\u001b[0m\ntests/test_config.py::TestGlobalConfigFunctions::test_load_config \u001b[32mPASSED\u001b[0m\u001b[31m [ 85%]\u001b[0m\ntests/test_config.py::TestGlobalConfigFunctions::test_get_audio_config \u001b[32mPASSED\u001b[0m\u001b[31m [ 90%]\u001b[0m\ntests/test_config.py::TestGlobalConfigFunctions::test_get_ai_config \u001b[32mPASSED\u001b[0m\u001b[31m [ 95%]\u001b[0m\ntests/test_config.py::TestGlobalConfigFunctions::test_get_security_config \u001b[32mPASSED\u001b[0m\u001b[31m [100%]\u001b[0m\n\n=================================== FAILURES ===================================\n\u001b[31m\u001b[1m_______________________ TestVoiceFlowConfig.test_to_dict _______________________\u001b[0m\n\u001b[1m\u001b[31mtests/test_config.py\u001b[0m:337: in test_to_dict\n    \u001b[0m\u001b[94massert\u001b[39;49;00m config.get(\u001b[33m'\u001b[39;49;00m\u001b[33maudio\u001b[39;49;00m\u001b[33m'\u001b[39;49;00m, \u001b[33m'\u001b[39;49;00m\u001b[33mmodel\u001b[39;49;00m\u001b[33m'\u001b[39;49;00m) == \u001b[33m'\u001b[39;49;00m\u001b[33mbase\u001b[39;49;00m\u001b[33m'\u001b[39;49;00m\u001b[90m\u001b[39;49;00m\n\u001b[1m\u001b[31mE   AssertionError: assert 'modified' == 'base'\u001b[0m\n\u001b[1m\u001b[31mE     \u001b[0m\n\u001b[1m\u001b[31mE     \u001b[0m\u001b[91m- base\u001b[39;49;00m\u001b[90m\u001b[39;49;00m\u001b[0m\n\u001b[1m\u001b[31mE     \u001b[92m+ modified\u001b[39;49;00m\u001b[90m\u001b[39;49;00m\u001b[0m\n\u001b[36m\u001b[1m=========================== short test summary info ============================\u001b[0m\n\u001b[31mFAILED\u001b[0m tests/test_config.py::\u001b[1mTestVoiceFlowConfig::test_to_dict\u001b[0m - AssertionError: assert 'modified' == 'base'\n  \n  \u001b[0m\u001b[91m- base\u001b[39;49;00m\u001b[90m\u001b[39;49;00m\n  \u001b[92m+ modified\u001b[39;49;00m\u001b[90m\u001b[39;49;00m\n\u001b[31m========================= \u001b[31m\u001b[1m1 failed\u001b[0m, \u001b[32m20 passed\u001b[0m\u001b[31m in 0.31s\u001b[0m\u001b[31m =========================\u001b[0m\n",
      "error_output": "",
      "exit_code": 1,
      "metadata": {}
    },
    {
      "name": "core_unit_tests",
      "test_type": "unit",
      "status": "failed",
      "duration": 1.505343,
      "start_time": "2025-07-13T10:47:44.843354",
      "end_time": "2025-07-13T10:47:46.348697",
      "output": "\u001b[1m============================= test session starts ==============================\u001b[0m\nplatform linux -- Python 3.12.11, pytest-8.4.1, pluggy-1.6.0 -- /data/data/com.termux/files/usr/bin/python3\ncachedir: .pytest_cache\nrootdir: /data/data/com.termux/files/home/projexta/voiceflow\nconfigfile: pytest.ini\nplugins: asyncio-1.0.0, anyio-4.9.0\nasyncio: mode=Mode.STRICT, asyncio_default_fixture_loop_scope=None, asyncio_default_test_loop_scope=function\n\u001b[1mcollecting ... \u001b[0mcollected 0 items / 1 error\n\n==================================== ERRORS ====================================\n\u001b[31m\u001b[1m________________ ERROR collecting tests/test_voiceflow_core.py _________________\u001b[0m\n\u001b[1m\u001b[31m../../../usr/lib/python3.12/site-packages/Xlib/support/unix_connect.py\u001b[0m:76: in get_socket\n    \u001b[0ms.connect(\u001b[33m'\u001b[39;49;00m\u001b[33m/tmp/.X11-unix/X\u001b[39;49;00m\u001b[33m%d\u001b[39;49;00m\u001b[33m'\u001b[39;49;00m % dno)\u001b[90m\u001b[39;49;00m\n\u001b[1m\u001b[31mE   FileNotFoundError: [Errno 2] No such file or directory\u001b[0m\n\n\u001b[33mDuring handling of the above exception, another exception occurred:\u001b[0m\n\u001b[1m\u001b[31mtests/test_voiceflow_core.py\u001b[0m:26: in <module>\n    \u001b[0m\u001b[94mfrom\u001b[39;49;00m\u001b[90m \u001b[39;49;00m\u001b[04m\u001b[96mcore\u001b[39;49;00m\u001b[04m\u001b[96m.\u001b[39;49;00m\u001b[04m\u001b[96mvoiceflow_core\u001b[39;49;00m\u001b[90m \u001b[39;49;00m\u001b[94mimport\u001b[39;49;00m VoiceFlowEngine, create_engine\u001b[90m\u001b[39;49;00m\n\u001b[1m\u001b[31mcore/__init__.py\u001b[0m:8: in <module>\n    \u001b[0m\u001b[94mfrom\u001b[39;49;00m\u001b[90m \u001b[39;49;00m\u001b[04m\u001b[96m.\u001b[39;49;00m\u001b[04m\u001b[96mvoiceflow_core\u001b[39;49;00m\u001b[90m \u001b[39;49;00m\u001b[94mimport\u001b[39;49;00m VoiceFlowEngine, create_engine\u001b[90m\u001b[39;49;00m\n\u001b[1m\u001b[31mcore/voiceflow_core.py\u001b[0m:18: in <module>\n    \u001b[0m\u001b[94mfrom\u001b[39;49;00m\u001b[90m \u001b[39;49;00m\u001b[04m\u001b[96m.\u001b[39;49;00m\u001b[04m\u001b[96mide_integration\u001b[39;49;00m\u001b[90m \u001b[39;49;00m\u001b[94mimport\u001b[39;49;00m create_ide_manager, IDEIntegrationManager\u001b[90m\u001b[39;49;00m\n\u001b[1m\u001b[31mcore/ide_integration.py\u001b[0m:29: in <module>\n    \u001b[0m\u001b[94mimport\u001b[39;49;00m\u001b[90m \u001b[39;49;00m\u001b[04m\u001b[96mpyautogui\u001b[39;49;00m\u001b[90m\u001b[39;49;00m\n\u001b[1m\u001b[31m../../../usr/lib/python3.12/site-packages/pyautogui/__init__.py\u001b[0m:246: in <module>\n    \u001b[0m\u001b[94mimport\u001b[39;49;00m\u001b[90m \u001b[39;49;00m\u001b[04m\u001b[96mmouseinfo\u001b[39;49;00m\u001b[90m\u001b[39;49;00m\n\u001b[1m\u001b[31m../../../usr/lib/python3.12/site-packages/mouseinfo/__init__.py\u001b[0m:223: in <module>\n    \u001b[0m_display = Display(os.environ[\u001b[33m'\u001b[39;49;00m\u001b[33mDISPLAY\u001b[39;49;00m\u001b[33m'\u001b[39;49;00m])\u001b[90m\u001b[39;49;00m\n               ^^^^^^^^^^^^^^^^^^^^^^^^^^^^^^\u001b[90m\u001b[39;49;00m\n\u001b[1m\u001b[31m../../../usr/lib/python3.12/site-packages/Xlib/display.py\u001b[0m:80: in __init__\n    \u001b[0m\u001b[96mself\u001b[39;49;00m.display = _BaseDisplay(display)\u001b[90m\u001b[39;49;00m\n                   ^^^^^^^^^^^^^^^^^^^^^\u001b[90m\u001b[39;49;00m\n\u001b[1m\u001b[31m../../../usr/lib/python3.12/site-packages/Xlib/display.py\u001b[0m:62: in __init__\n    \u001b[0mdisplay.Display.\u001b[92m__init__\u001b[39;49;00m(*(\u001b[96mself\u001b[39;49;00m, ) + args, **keys)\u001b[90m\u001b[39;49;00m\n\u001b[1m\u001b[31m../../../usr/lib/python3.12/site-packages/Xlib/protocol/display.py\u001b[0m:58: in __init__\n    \u001b[0m\u001b[96mself\u001b[39;49;00m.socket = connect.get_socket(name, host, displayno)\u001b[90m\u001b[39;49;00m\n                  ^^^^^^^^^^^^^^^^^^^^^^^^^^^^^^^^^^^^^^^^^\u001b[90m\u001b[39;49;00m\n\u001b[1m\u001b[31m../../../usr/lib/python3.12/site-packages/Xlib/support/connect.py\u001b[0m:76: in get_socket\n    \u001b[0m\u001b[94mreturn\u001b[39;49;00m mod.get_socket(dname, host, dno)\u001b[90m\u001b[39;49;00m\n           ^^^^^^^^^^^^^^^^^^^^^^^^^^^^^^^^\u001b[90m\u001b[39;49;00m\n\u001b[1m\u001b[31m../../../usr/lib/python3.12/site-packages/Xlib/support/unix_connect.py\u001b[0m:78: in get_socket\n    \u001b[0m\u001b[94mraise\u001b[39;49;00m error.DisplayConnectionError(dname, \u001b[96mstr\u001b[39;49;00m(val))\u001b[90m\u001b[39;49;00m\n\u001b[1m\u001b[31mE   Xlib.error.DisplayConnectionError: Can't connect to display \":99\": [Errno 2] No such file or directory\u001b[0m\n\u001b[36m\u001b[1m=========================== short test summary info ============================\u001b[0m\n\u001b[31mERROR\u001b[0m tests/test_voiceflow_core.py - Xlib.error.DisplayConnectionError: Can't connect to display \":99\": [Errno 2] No such file or directory\n!!!!!!!!!!!!!!!!!!!! Interrupted: 1 error during collection !!!!!!!!!!!!!!!!!!!!\n\u001b[31m=============================== \u001b[31m\u001b[1m1 error\u001b[0m\u001b[31m in 0.71s\u001b[0m\u001b[31m ===============================\u001b[0m\n",
      "error_output": "",
      "exit_code": 2,
      "metadata": {}
    },
    {
      "name": "ai_enhancement_tests",
      "test_type": "unit",
      "status": "failed",
      "duration": 1.575499,
      "start_time": "2025-07-13T10:47:44.844298",
      "end_time": "2025-07-13T10:47:46.419797",
      "output": "\u001b[1m============================= test session starts ==============================\u001b[0m\nplatform linux -- Python 3.12.11, pytest-8.4.1, pluggy-1.6.0 -- /data/data/com.termux/files/usr/bin/python3\ncachedir: .pytest_cache\nrootdir: /data/data/com.termux/files/home/projexta/voiceflow\nconfigfile: pytest.ini\nplugins: asyncio-1.0.0, anyio-4.9.0\nasyncio: mode=Mode.STRICT, asyncio_default_fixture_loop_scope=None, asyncio_default_test_loop_scope=function\n\u001b[1mcollecting ... \u001b[0mcollected 0 items / 1 error\n\n==================================== ERRORS ====================================\n\u001b[31m\u001b[1m________________ ERROR collecting tests/test_ai_enhancement.py _________________\u001b[0m\n\u001b[1m\u001b[31m../../../usr/lib/python3.12/site-packages/Xlib/support/unix_connect.py\u001b[0m:76: in get_socket\n    \u001b[0ms.connect(\u001b[33m'\u001b[39;49;00m\u001b[33m/tmp/.X11-unix/X\u001b[39;49;00m\u001b[33m%d\u001b[39;49;00m\u001b[33m'\u001b[39;49;00m % dno)\u001b[90m\u001b[39;49;00m\n\u001b[1m\u001b[31mE   FileNotFoundError: [Errno 2] No such file or directory\u001b[0m\n\n\u001b[33mDuring handling of the above exception, another exception occurred:\u001b[0m\n\u001b[1m\u001b[31mtests/test_ai_enhancement.py\u001b[0m:22: in <module>\n    \u001b[0m\u001b[94mfrom\u001b[39;49;00m\u001b[90m \u001b[39;49;00m\u001b[04m\u001b[96mcore\u001b[39;49;00m\u001b[04m\u001b[96m.\u001b[39;49;00m\u001b[04m\u001b[96mai_enhancement\u001b[39;49;00m\u001b[90m \u001b[39;49;00m\u001b[94mimport\u001b[39;49;00m AIEnhancer, create_enhancer\u001b[90m\u001b[39;49;00m\n\u001b[1m\u001b[31mcore/__init__.py\u001b[0m:8: in <module>\n    \u001b[0m\u001b[94mfrom\u001b[39;49;00m\u001b[90m \u001b[39;49;00m\u001b[04m\u001b[96m.\u001b[39;49;00m\u001b[04m\u001b[96mvoiceflow_core\u001b[39;49;00m\u001b[90m \u001b[39;49;00m\u001b[94mimport\u001b[39;49;00m VoiceFlowEngine, create_engine\u001b[90m\u001b[39;49;00m\n\u001b[1m\u001b[31mcore/voiceflow_core.py\u001b[0m:18: in <module>\n    \u001b[0m\u001b[94mfrom\u001b[39;49;00m\u001b[90m \u001b[39;49;00m\u001b[04m\u001b[96m.\u001b[39;49;00m\u001b[04m\u001b[96mide_integration\u001b[39;49;00m\u001b[90m \u001b[39;49;00m\u001b[94mimport\u001b[39;49;00m create_ide_manager, IDEIntegrationManager\u001b[90m\u001b[39;49;00m\n\u001b[1m\u001b[31mcore/ide_integration.py\u001b[0m:29: in <module>\n    \u001b[0m\u001b[94mimport\u001b[39;49;00m\u001b[90m \u001b[39;49;00m\u001b[04m\u001b[96mpyautogui\u001b[39;49;00m\u001b[90m\u001b[39;49;00m\n\u001b[1m\u001b[31m../../../usr/lib/python3.12/site-packages/pyautogui/__init__.py\u001b[0m:246: in <module>\n    \u001b[0m\u001b[94mimport\u001b[39;49;00m\u001b[90m \u001b[39;49;00m\u001b[04m\u001b[96mmouseinfo\u001b[39;49;00m\u001b[90m\u001b[39;49;00m\n\u001b[1m\u001b[31m../../../usr/lib/python3.12/site-packages/mouseinfo/__init__.py\u001b[0m:223: in <module>\n    \u001b[0m_display = Display(os.environ[\u001b[33m'\u001b[39;49;00m\u001b[33mDISPLAY\u001b[39;49;00m\u001b[33m'\u001b[39;49;00m])\u001b[90m\u001b[39;49;00m\n               ^^^^^^^^^^^^^^^^^^^^^^^^^^^^^^\u001b[90m\u001b[39;49;00m\n\u001b[1m\u001b[31m../../../usr/lib/python3.12/site-packages/Xlib/display.py\u001b[0m:80: in __init__\n    \u001b[0m\u001b[96mself\u001b[39;49;00m.display = _BaseDisplay(display)\u001b[90m\u001b[39;49;00m\n                   ^^^^^^^^^^^^^^^^^^^^^\u001b[90m\u001b[39;49;00m\n\u001b[1m\u001b[31m../../../usr/lib/python3.12/site-packages/Xlib/display.py\u001b[0m:62: in __init__\n    \u001b[0mdisplay.Display.\u001b[92m__init__\u001b[39;49;00m(*(\u001b[96mself\u001b[39;49;00m, ) + args, **keys)\u001b[90m\u001b[39;49;00m\n\u001b[1m\u001b[31m../../../usr/lib/python3.12/site-packages/Xlib/protocol/display.py\u001b[0m:58: in __init__\n    \u001b[0m\u001b[96mself\u001b[39;49;00m.socket = connect.get_socket(name, host, displayno)\u001b[90m\u001b[39;49;00m\n                  ^^^^^^^^^^^^^^^^^^^^^^^^^^^^^^^^^^^^^^^^^\u001b[90m\u001b[39;49;00m\n\u001b[1m\u001b[31m../../../usr/lib/python3.12/site-packages/Xlib/support/connect.py\u001b[0m:76: in get_socket\n    \u001b[0m\u001b[94mreturn\u001b[39;49;00m mod.get_socket(dname, host, dno)\u001b[90m\u001b[39;49;00m\n           ^^^^^^^^^^^^^^^^^^^^^^^^^^^^^^^^\u001b[90m\u001b[39;49;00m\n\u001b[1m\u001b[31m../../../usr/lib/python3.12/site-packages/Xlib/support/unix_connect.py\u001b[0m:78: in get_socket\n    \u001b[0m\u001b[94mraise\u001b[39;49;00m error.DisplayConnectionError(dname, \u001b[96mstr\u001b[39;49;00m(val))\u001b[90m\u001b[39;49;00m\n\u001b[1m\u001b[31mE   Xlib.error.DisplayConnectionError: Can't connect to display \":99\": [Errno 2] No such file or directory\u001b[0m\n\u001b[36m\u001b[1m=========================== short test summary info ============================\u001b[0m\n\u001b[31mERROR\u001b[0m tests/test_ai_enhancement.py - Xlib.error.DisplayConnectionError: Can't connect to display \":99\": [Errno 2] No such file or directory\n!!!!!!!!!!!!!!!!!!!! Interrupted: 1 error during collection !!!!!!!!!!!!!!!!!!!!\n\u001b[31m=============================== \u001b[31m\u001b[1m1 error\u001b[0m\u001b[31m in 0.75s\u001b[0m\u001b[31m ===============================\u001b[0m\n",
      "error_output": "",
      "exit_code": 2,
      "metadata": {}
    }
  ],
  "system_stats": {},
  "config": {
    "max_parallel_tests": 4,
    "enable_parallel_execution": true,
    "fail_fast": false
  }
}